<?xml version="1.0"?>
<robot name="hexapod_bot">

  <material name="red">
    <color rgba="0.8 0 0 1"/>
  </material>
  <material name="black">
    <color rgba="0.1 0.1 0.1 1"/>
  </material>
  <material name="silver">
    <color rgba="0.75 0.75 0.75 1"/>
  </material>

  <link name="base_link">
    <visual>
      <geometry>
        <mesh filename="package://my_hexapod/meshes/base.stl" />
      </geometry>
      <material name="black"/>
      <origin xyz="0 0 0" rpy="0 0 0"/>
    </visual>
  </link>


  <joint name="joint_1_coxa" type="revolute">
    <parent link="base_link"/>
    <child link="leg_1_coxa"/>
    <origin xyz="0.0845 0.0668 0" rpy="0 0 0.668"/> <axis xyz="0 0 1"/> <limit lower="-1.57" upper="1.57" effort="1000" velocity="1.0"/>
  </joint>

  <link name="leg_1_coxa">
    <visual>
      <geometry>
        <mesh filename="package://my_hexapod/meshes/coxa.stl"/>
      </geometry>
      <origin xyz="0 0 0" rpy="0 0 0"/> <material name="red"/>
    </visual>
  </link>


  <joint name="joint_1_femur" type="revolute">
    <parent link="leg_1_coxa"/>
    <child link="leg_1_femur"/>
    <origin xyz="0.0464 0 0.015" rpy="0 0 0"/> <axis xyz="0 1 0"/> <limit lower="-1.57" upper="1.57" effort="1000" velocity="1.0"/>
  </joint>

  <link name="leg_1_femur">
    <visual>
      <geometry>
        <mesh filename="package://my_hexapod/meshes/femur.stl"/>
      </geometry>
      <origin xyz="0 0 0" rpy="0 0 0"/> <material name="silver"/>
    </visual>
  </link>


  <joint name="joint_1_tibia" type="revolute">
    <parent link="leg_1_femur"/>
    <child link="leg_1_tibia"/>
    <origin xyz="0.11 0 0" rpy="0 0 0"/> <axis xyz="0 1 0"/> <limit lower="-3.14" upper="3.14" effort="1000" velocity="1.0"/>
  </joint>

  <link name="leg_1_tibia">
    <visual>
      <geometry>
        <mesh filename="package://my_hexapod/meshes/tibia.stl"/>
      </geometry>
      <origin xyz="0 0 0" rpy="0 0 0"/>
      <material name="black"/>
    </visual>
  </link>

</robot>